Traceback (most recent call last):
  File "/usr/local/lib/python3.11/dist-packages/jupyter_core/utils/__init__.py", line 154, in wrapped
    asyncio.get_running_loop()
RuntimeError: no running event loop

During handling of the above exception, another exception occurred:

Traceback (most recent call last):
  File "/usr/local/lib/python3.11/dist-packages/jupyter_cache/executors/utils.py", line 58, in single_nb_execution
    executenb(
  File "/usr/local/lib/python3.11/dist-packages/nbclient/client.py", line 1319, in execute
    return NotebookClient(nb=nb, resources=resources, km=km, **kwargs).execute()
           ^^^^^^^^^^^^^^^^^^^^^^^^^^^^^^^^^^^^^^^^^^^^^^^^^^^^^^^^^^^^^^^^^^^^^
  File "/usr/local/lib/python3.11/dist-packages/jupyter_core/utils/__init__.py", line 158, in wrapped
    return loop.run_until_complete(inner)
           ^^^^^^^^^^^^^^^^^^^^^^^^^^^^^^
  File "/usr/lib/python3.11/asyncio/base_events.py", line 654, in run_until_complete
    return future.result()
           ^^^^^^^^^^^^^^^
  File "/usr/local/lib/python3.11/dist-packages/nbclient/client.py", line 709, in async_execute
    await self.async_execute_cell(
  File "/usr/local/lib/python3.11/dist-packages/nbclient/client.py", line 1062, in async_execute_cell
    await self._check_raise_for_error(cell, cell_index, exec_reply)
  File "/usr/local/lib/python3.11/dist-packages/nbclient/client.py", line 918, in _check_raise_for_error
    raise CellExecutionError.from_cell_and_msg(cell, exec_reply_content)
nbclient.exceptions.CellExecutionError: An error occurred while executing the following cell:
------------------
from sklearn.neighbors import LocalOutlierFactor
import numpy as np


lof = LocalOutlierFactor(n_neighbors=20, contamination='auto')

outlier_labels = lof.fit_predict(X_scaled_df)

lof_scores = lof.negative_outlier_factor_

X_scaled_df['lof_score'] = lof_scores
X_scaled_df['is_outlier'] = outlier_labels

print("Samples with lowest LOF scores (most likely outliers):")
display(X_scaled_df.sort_values(by='lof_score').head())

print("\nCount of outliers (-1) and inliers (1):")
print(X_scaled_df['is_outlier'].value_counts())
------------------


[0;31m---------------------------------------------------------------------------[0m
[0;31mNameError[0m                                 Traceback (most recent call last)
[0;32m/tmp/ipython-input-10-757295879.py[0m in [0;36m<cell line: 0>[0;34m()[0m
[1;32m      5[0m [0mlof[0m [0;34m=[0m [0mLocalOutlierFactor[0m[0;34m([0m[0mn_neighbors[0m[0;34m=[0m[0;36m20[0m[0;34m,[0m [0mcontamination[0m[0;34m=[0m[0;34m'auto'[0m[0;34m)[0m[0;34m[0m[0;34m[0m[0m
[1;32m      6[0m [0;34m[0m[0m
[0;32m----> 7[0;31m [0moutlier_labels[0m [0;34m=[0m [0mlof[0m[0;34m.[0m[0mfit_predict[0m[0;34m([0m[0mX_scaled_df[0m[0;34m)[0m[0;34m[0m[0;34m[0m[0m
[0m[1;32m      8[0m [0;34m[0m[0m
[1;32m      9[0m [0mlof_scores[0m [0;34m=[0m [0mlof[0m[0;34m.[0m[0mnegative_outlier_factor_[0m[0;34m[0m[0;34m[0m[0m

[0;31mNameError[0m: name 'X_scaled_df' is not defined

